Workbook

Sheet Historical Trends
A1: license_start_year | B1: license_count | D1: =export_yearly_trends[[#Headers],[license_start_year]] -> license_start_year | E1: =export_yearly_trends[[#Headers],[license_count]] -> license_count
A2: 1900 | B2: 2 | D2: 2000 | E2: 134
A3: 1910 | B3: 1 | D3: 2001 | E3: 131
A4: 1941 | B4: 1 | D4: 2002 | E4: 152
A5: 1942 | B5: 1 | D5: 2003 | E5: 176
A6: 1944 | B6: 1 | D6: 2004 | E6: 170
A7: 1946 | B7: 1 | D7: 2005 | E7: 173
A8: 1949 | B8: 1 | D8: 2006 | E8: 183
A9: 1950 | B9: 1 | D9: 2007 | E9: 245
A10: 1953 | B10: 1 | D10: 2008 | E10: 275
A11: 1954 | B11: 2 | D11: 2009 | E11: 314
A12: 1955 | B12: 1 | D12: 2010 | E12: 232
A13: 1957 | B13: 1 | D13: 2011 | E13: 262
... A28: 1972 | B28: 6 | D28: 2026 | E28: 695
A29: 1973 | B29: 9
A30: 1974 | B30: 8
A31: 1975 | B31: 8
A32: 1976 | B32: 16
A33: 1977 | B33: 11
A34: 1978 | B34: 13
A35: 1979 | B35: 7
A36: 1980 | B36: 17
A37: 1981 | B37: 16
A38: 1982 | B38: 28
A39: 1983 | B39: 29
A40: 1984 | B40: 40
... A82: 2026 | B82: 695

Sheet Industry Analysis
A1: naics_description | B1: license_count | C1: share_of_total
A2: Lessors of Residential Buildings and Dwellings | B2: 540 | C2: 4.19
A3: All Other Personal Services | B3: 461 | C3: 3.57
A4: Taxi and Ridesharing Services | B4: 418 | C4: 3.24
A5: All Other Transit and Ground Passenger Transportation | B5: 380 | C5: 2.95
A6: Offices of Mental Health Practitioners (except Physicians) | B6: 335 | C6: 2.6
A7: All Other Traveler Accommodation | B7: 329 | C7: 2.55
A8: Independent Artists, Writers, and Performers | B8: 284 | C8: 2.2
A9: All Other Miscellaneous Retailers | B9: 254 | C9: 1.97
A10: Administrative Management and General Management Consulting Services | B10: 246 | C10: 1.91
A11: Residential Remodelers | B11: 243 | C11: 1.88
A12: All Other Professional, Scientific, and Technical Services | B12: 239 | C12: 1.85
A13: Limited-Service Restaurants | B13: 204 | C13: 1.58
... A632: Direct Health and Medical Insurance Carriers | B632: 1 | C632: 0.01

Sheet Ownership Analysis
A1: ownership_type | B1: license_count | C1: share_of_total
A2: Sole proprietorship | B2: 3283 | C2: 25.46
A3: Corporation | B3: 3099 | C3: 24.03
A4: LLC - Single Member | B4: 2797 | C4: 21.69
A5: LLC - Multi Member | B5: 2622 | C5: 20.33
A6: Other | B6: 435 | C6: 3.37
A7: Non Profit Corporation | B7: 137 | C7: 1.06
A8: Association | B8: 109 | C8: 0.85
A9: Limited Liability Limited Ptrs | B9: 108 | C9: 0.84
A10: Professional Association | B10: 98 | C10: 0.76
A11: Limited Liability Ptrs LLP | B11: 88 | C11: 0.68
A12: General Partnership | B12: 87 | C12: 0.67
A13: Limited Partnership | B13: 20 | C13: 0.16
... A18: Tribal Government | B18: 1 | C18: 0.01

Sheet Age Groups
A1: business_age_group | B1: license_count
A2: 1–5 years | B2: 3961
A3: 11–20 years | B3: 2901
A4: 6–10 years | B4: 2678
A5: More than 20 years | B5: 2282
A6: Less than 1 year | B6: 1054
A7: Future start date | B7: 21

Sheet Geographic Analysis
A1: zip_5 | B1: license_count | C1: share_of_seattle_records
A2: 98103 | B2: 688 | C2: 7.81
A3: 98101 | B3: 529 | C3: 6.01
A4: 98118 | B4: 513 | C4: 5.83
A5: 98109 | B5: 471 | C5: 5.35
A6: 98107 | B6: 465 | C6: 5.28
A7: 98122 | B7: 460 | C7: 5.22
A8: 98115 | B8: 438 | C8: 4.97
A9: 98108 | B9: 373 | C9: 4.24
A10: 98104 | B10: 366 | C10: 4.16
A11: 98144 | B11: 364 | C11: 4.13
A12: 98117 | B12: 359 | C12: 4.08
A13: 98125 | B13: 337 | C13: 3.83
... A54: 98160 | B54: 1 | C54: 0.01

Sheet KPI Summary
A1: total_license_records | B1: unique_ubi_count | C1: seattle_address_records | D1: seattle_address_share | E1: average_business_age | F1: started_within_last_5_years | G1: future_dated_records
A2: 12897 | B2: 11659 | C2: 8805 | D2: 68.27 | E2: 11.31 | F2: 5015 | G2: 21
A4: Metric | B4: Value
A5: Total License Records | B5: {=export_kpis[total_license_records]} -> 12897
A6: Unique Businesses (UBI) | B6: {=export_kpis[unique_ubi_count]} -> 11659
A7: Seattle Address Records | B7: {=export_kpis[seattle_address_records]} -> 8805
A8: Seattle Address Share | B8: {=export_kpis[seattle_address_share]/100} -> 0.6827
A9: Average Business Age | B9: {=export_kpis[average_business_age]} -> 11.31
A10: Started Within Last 5 Years | B10: {=export_kpis[started_within_last_5_years]} -> 5015
A11: Future-Dated Records | B11: {=export_kpis[future_dated_records]} -> 21

Sheet Data Validation
A1: Check | B1: SQL Expected | C1: Excel Result | D1: Status
A2: Total License Records | B2: 12897 | C2: ='KPI Summary'!B5 -> 12897 | D2: =IF(B2=C2,"Match","Check") -> Match
A3: Unique UBIs | B3: 11659 | C3: ='KPI Summary'!B6 -> 11659 | D3: =IF(B3=C3,"Match","Check") -> Match
A4: Seattle Address Records | B4: 8805 | C4: ='KPI Summary'!B7 -> 8805 | D4: =IF(B4=C4,"Match","Check") -> Match
A5: Started Within Last 5 Years | B5: 5015 | C5: ='KPI Summary'!B10 -> 5015 | D5: =IF(B5=C5,"Match","Check") -> Match
A6: Future-Dated Records | B6: 21 | C6: ='KPI Summary'!B11 -> 21 | D6: =IF(B6=C6,"Match","Check") -> Match
A7: Age Group Total | B7: 12897 | C7: =SUM('Age Groups'!B2:B7) -> 12897 | D7: =IF(B7=C7,"Match","Check") -> Match

Sheet Analysis Data
A1: business_legal_name | B1: trade_name | C1: ownership_type | D1: naics_code | E1: naics_description | F1: naics_sector | G1: license_start_date | H1: license_start_year | I1: business_age_years | J1: business_age_group | K1: is_future_start_date | L1: street_address | M1: city | N1: state | O1: zip_5 | P1: is_seattle_address | Q1: city_account_number | R1: ubi
A2: ABDURAKHMANOV RASUL | B2: RASUL ABDURAKHMANOV | C2: Sole proprietorship | D2: 485320 | E2: Limousine Service | F2: 48 | G2: 41865 | H2: 2014 | I2: 11 | J2: 11–20 years | K2: 0 | L2: 706 UNION ST # 409 | M2: SEATTLE | N2: WA | O2: 98101 | P2: 1 | Q2: 7748490686809
A3: AHMED MUSTAFE F | B3: MUSTAFE F AHMED | C3: Sole proprietorship | D3: 485999 | E3: All Other Transit and Ground Passenger Transportation | F3: 48 | G3: 41950 | H3: 2014 | I3: 11 | J3: 11–20 years | K3: 0 | L3: 14203 42ND AVE S # 221 | M3: TUKWILA | N3: WA | O3: 98168 | P3: 0 | Q3: 7760940688081
A4: BUI PHUONG | B4: BUI PHUONG | C4: Sole proprietorship | D4: 721191 | E4: Bed-and-Breakfast Inns | F4: 72 | G4: 43704 | H4: 2019 | I4: 6 | J4: 6–10 years | K4: 0 | L4: 2324 1ST AVE #313 | M4: SEATTLE | N4: WA | O4: 98121 | P4: 1 | Q4: 8410320755821 | R4: 6.0449957e+15
A5: CRUZ BRENDAN J | B5: PHENOMENAL PHILLIE | C5: Sole proprietorship | D5: 311811 | E5: Retail Bakeries | F5: 31 | G5: 44774 | H5: 2022 | I5: 4 | J5: 1–5 years | K5: 0 | L5: 4130 PALATINE AVE N | M5: SEATTLE | N5: WA | O5: 98103 | P5: 1 | Q5: 8621920778133 | R5: 604913720
A6: DAVID ANTHONY LEWIS PS | B6: DAVID ANTHONY LEWIS PS | C6: Corporation | D6: 611699 | E6: All Other Miscellaneous Schools and Instruction | F6: 61 | G6: 44595 | H6: 2022 | I6: 4 | J6: 1–5 years | K6: 0 | L6: 8707 16TH AVE SW | M6: SEATTLE | N6: WA | O6: 98106 | P6: 1 | Q6: 8590290774829 | R6: 6.0350592e+15
A7: GATES FOUNDATION TRUST | B7: GATES FOUNDATION TRUST | C7: Other | D7: 813211 | E7: Grantmaking Foundations | F7: 81 | G7: 36526 | H7: 2000 | I7: 26 | J7: More than 20 years | K7: 0 | L7: 500 5TH AVE N | M7: SEATTLE | N7: WA | O7: 98109 | P7: 1 | Q7: 5329790536018 | R7: 6.0159714e+15
A8: INDERJIT TAXI | B8: INDERJIT TAXI | C8: Sole proprietorship | D8: 485310 | E8: Taxi and Ridesharing Services | F8: 48 | G8: 45868 | H8: 2025 | I8: 1 | J8: 1–5 years | K8: 0 | L8: 2464 S 296TH PL | M8: FEDERAL WAY | N8: WA | O8: 98003 | P8: 0 | Q8: 8853030802536
A9: JUGRAJ BRAR | B9: JUGRAJ BRAR | C9: Sole proprietorship | D9: 485999 | E9: All Other Transit and Ground Passenger Transportation | F9: 48 | G9: 41983 | H9: 2014 | I9: 11 | J9: 11–20 years | K9: 0 | L9: 30036 65TH AVE S | M9: AUBURN | N9: WA | O9: 98001 | P9: 0 | Q9: 7777700689807 | R9: 7777700689807
A10: LYKKEN JOSEPH ALAN | B10: JOSEPH A LYKKEN | C10: Sole proprietorship | D10: 721191 | E10: Bed-and-Breakfast Inns | F10: 72 | G10: 43814 | H10: 2019 | I10: 6 | J10: 6–10 years | K10: 0 | L10: 519 32ND AVE E | M10: SEATTLE | N10: WA | O10: 98112 | P10: 1 | Q10: 8439890758892 | R10: 6.0452344e+15
A11: MANGASTO ZERFE W | B11: MANGSTO ZERFE | C11: Sole proprietorship | D11: 485320 | E11: Limousine Service | F11: 48 | G11: 42144 | H11: 2015 | I11: 11 | J11: 11–20 years | K11: 0 | L11: 17210 30TH AVE S # H11 | M11: SEATAC | N11: WA | O11: 98188 | P11: 0 | Q11: 7833790695669
A12: MERKEL JR JOEL C & REYNEVELD SARAH | B12: MERKEL JR JOEL C | C12: Sole proprietorship | D12: 721191 | E12: Bed-and-Breakfast Inns | F12: 72 | G12: 42644 | H12: 2016 | I12: 9 | J12: 6–10 years | K12: 0 | L12: 7353 16TH AVE NW | M12: SEATTLE | N12: WA | O12: 98117 | P12: 1 | Q12: 8370590751644 | R12: 6.0428551e+15
A13: MOTS LLC | B13: LOAD RUNNER | C13: LLC - Single Member | D13: 812990 | E13: All Other Personal Services | F13: 81 | G13: 44126 | H13: 2020 | I13: 5 | J13: 1–5 years | K13: 0 | L13: 1012 S HENDERSON ST # B | M13: SEATTLE | N13: WA | O13: 98108 | P13: 1 | Q13: 8503350765696 | R13: 6.0429548e+15
A14: PERKINS EASTMAN ARCHITECTS DPC | B14: PERKINS EASTMAN ARCHITECTS DPC | C14: Corporation | D14: 541310 | E14: Architectural Services | F14: 54 | G14: 41275 | H14: 2013 | I14: 13 | J14: 11–20 years | K14: 0 | L14: 115 5TH AVE # 3 | M14: NEW YORK | N14: NY | O14: 10003 | P14: 0 | Q14: 8360110750546 | R14: 6.032434e+15
A15: PLANET WISE SOLUTIONS | B15: PLANET WISE SOLUTIONS | C15: Association | D15: 812990 | E15: All Other Personal Services | F15: 81 | G15: 39545 | H15: 2008 | I15: 18 | J15: 11–20 years | K15: 0 | L15: 13714 37TH AVE NE | M15: SEATTLE | N15: WA | O15: 98125 | P15: 1 | Q15: 7069140614696 | R15: 6.0282056e+15
A16: ROOTED RITUAL SALON LLC | B16: ROOTED RITUAL SALON | C16: LLC - Single Member | D16: 812112 | E16: Beauty Salons | F16: 81 | G16: 43157 | H16: 2018 | I16: 8 | J16: 6–10 years | K16: 0 | L16: 1416 NW BALLARD WAY | M16: SEATTLE | N16: WA | O16: 98107 | P16: 1 | Q16: 8185690732262 | R16: 6.0420011e+15
A17: SCHNITZER PROPERTIES MANAGEMENT LLC | B17: HARSCH INVESTMENT PROPERTIES MANAGEMENT LLC | C17: LLC - Multi Member | D17: 531210 | E17: Offices of Real Estate Agents and Brokers | F17: 53 | G17: 37074 | H17: 2001 | I17: 25 | J17: More than 20 years | K17: 0 | L17: 309 S CLOVERDALE ST # B14 | M17: SEATTLE | N17: WA | O17: 98108 | P17: 1 | Q17: 5515700555922 | R17: 6.0213351e+15
A18: THIND MANJIT SINGH | B18: MANJIT SINGH THIND | C18: Sole proprietorship | D18: 485999 | E18: All Other Transit and Ground Passenger Transportation | F18: 48 | G18: 41981 | H18: 2014 | I18: 11 | J18: 11–20 years | K18: 0 | L18: 13229 SE 234TH ST | M18: KENT | N18: WA | O18: 98042 | P18: 0 | Q18: 7776510689683
A19: VERDANT COMMERCIAL CAPITAL LLC | B19: VERDANT COMMERCIAL CAPITAL LLC | C19: LLC - Single Member | D19: 532420 | E19: Office Machinery and Equipment Rental and Leasing | F19: 53 | G19: 43101 | H19: 2018 | I19: 8 | J19: 6–10 years | K19: 0 | L19: 9987 CARVER RD # 110 | M19: CINCINNATI | N19: OH | O19: 45242 | P19: 0 | Q19: 8829560800100 | R19: 6.0430759e+15
A20: #1 SEATTLE LUXURY ADULT FAMILY HOME | B20: SEATTLE LUXURY ADULT FAMILY HOME | C20: LLC - Multi Member | D20: 623990 | E20: Other Residential Care Facilities | F20: 62 | G20: 45839 | H20: 2025 | I20: 1 | J20: 1–5 years | K20: 0 | L20: 10006 SAND POINT WAY NE | M20: SEATTLE | N20: WA | O20: 98125 | P20: 1 | Q20: 8831440800297 | R20: 6.056395e+15
A21: 0 BLOK LLC | B21: 0BLOK | C21: LLC - Single Member | D21: 541310 | E21: Architectural Services | F21: 54 | G21: 44405 | H21: 2021 | I21: 5 | J21: 1–5 years | K21: 0 | L21: 515 29TH AVE S | M21: SEATTLE | N21: WA | O21: 98144 | P21: 1 | Q21: 8551870770776 | R21: 6.0476766e+15
A22: 002 LIMA LLC | B22: 002 LIMA LLC | C22: LLC - Single Member | D22: 531110 | E22: Lessors of Residential Buildings and Dwellings | F22: 53 | G22: 45061 | H22: 2023 | I22: 3 | J22: 1–5 years | K22: 0 | L22: 4515C SUNNYSIDE AVE N | M22: SEATTLE | N22: WA | O22: 98103 | P22: 1 | Q22: 8683360784544 | R22: 6.050156e+15
A23: 003 LLC | B23: 003 LLC | C23: LLC - Multi Member | D23: 561320 | E23: Temporary Help Services | F23: 56 | G23: 42186 | H23: 2015 | I23: 11 | J23: 11–20 years | K23: 0 | L23: 1500 WESTLAKE AVE N # 212 | M23: SEATTLE | N23: WA | O23: 98109 | P23: 1 | Q23: 7861530698534 | R23: 6.0313493e+15
A24: 080 NETWORKS | B24: 080NETWORKS | C24: LLC - Multi Member | D24: 541511 | E24: Custom Computer Programming Services | F24: 54 | G24: 39680 | H24: 2008 | I24: 17 | J24: 11–20 years | K24: 0 | L24: 1676 NORTHLAKE WAY NW | M24: BREMERTON | N24: WA | O24: 98312 | P24: 0 | Q24: 7111560619170 | R24: 6.028583e+15
A25: 0982563 BC LTD | B25: SURGE PRODUCTIONS | C25: Corporation | D25: 711320 | E25: Promoters of Performing Arts, Sports, and Similar Events without Facilities | F25: 71 | G25: 42741 | H25: 2017 | I25: 9 | J25: 6–10 years | K25: 0 | L25: 101 215 OSWEGO ST | M25: VICTORIA | N25: BC | O25: V8V 2 | P25: 0 | Q25: 8356270750132 | R25: 6.0407742e+15
A26: 1 AD STUDIO | B26: 1 AD STUDIO | C26: LLC - Multi Member | D26: 541410 | E26: Interior Design Services | F26: 54 | G26: 42089 | H26: 2015 | I26: 11 | J26: 11–20 years | K26: 0 | L26: 3270 41ST AVE SW | M26: SEATTLE | N26: WA | O26: 98116 | P26: 1 | Q26: 7817000693916 | R26: 6.0349199e+15
A27: 1 FINE AUTO LLC | B27: RICHS CUSTOM UPHOLSTERY | C27: LLC - Multi Member | D27: 811121 | E27: Automotive Body, Paint, and Interior Repair and Maintenance | F27: 81 | G27: 39904 | H27: 2009 | I27: 17 | J27: 11–20 years | K27: 0 | L27: 10003 AURORA AVE N | M27: SEATTLE | N27: WA | O27: 98133 | P27: 1 | Q27: 7173520625939 | R27: 6.0290209e+15
A28: 1 LIFE CONSTRUCTION INC | B28: PIPE DR & AFFORDABLE SEWER & DRAIN | C28: Corporation | D28: 236118 | E28: Residential Remodelers | F28: 23 | G28: 41821 | H28: 2014 | I28: 12 | J28: 11–20 years | K28: 0 | L28: 12345 LAKE CITY WAY NE # 311 | M28: SEATTLE | N28: WA | O28: 98125 | P28: 1 | Q28: 7895510702061 | R28: 6.0342172e+15
A29: 1 NEW MECHANICAL LLC | B29: 1 NEW MECHANICAL LLC | C29: LLC - Single Member | D29: 238220 | E29: Plumbing, Heating, and Air-Conditioning Contractors | F29: 23 | G29: 43776 | H29: 2019 | I29: 6 | J29: 6–10 years | K29: 0 | L29: 11906 206TH AVE SE | M29: SNOHOMISH | N29: WA | O29: 98290 | P29: 0 | Q29: 8430560757910 | R29: 6.0409739e+15
A30: 1 PRO NAILS LLC | B30: 1 PRO NAILS | C30: LLC - Multi Member | D30: 812112 | E30: Beauty Salons | F30: 81 | G30: 37622 | H30: 2003 | I30: 23 | J30: More than 20 years | K30: 0 | L30: 18 ROY ST | M30: SEATTLE | N30: WA | O30: 98109 | P30: 1 | Q30: 5574740562230 | R30: 6.0225133e+15
... A154: 1556 NW 62ND STREET LLC | B154: 1556 NW 62ND STREET LLC | C154: LLC - Single Member | D154: 531110 | E154: Lessors of Residential Buildings and Dwellings | F154: 53 | G154: 45383 | H154: 2024 | I154: 2 | J154: 1–5 years | K154: 0 | L154: 330 ARIA LN | M154: WENATCHEE | N154: WA | O154: 98801 | P154: 0 | Q154: 8745500791145 | R154: 6.0543129e+15
A155: 1560 RENTAL | B155: KEVIN BURTCHAELL | C155: Sole proprietorship | D155: 721191 | E155: Bed-and-Breakfast Inns | F155: 72 | G155: 45272 | H155: 2023 | I155: 2 | J155: 1–5 years | K155: 0 | L155: 1560 NE 106TH ST | M155: SEATTLE | N155: WA | O155: 98125 | P155: 1 | Q155: 8726750789189
A156: 15TH AVE EAST MERCHANTS ASSOC | B156: 15TH AVE EAST MERCHANTS ASSOC | C156: Association | D156: 813910 | E156: Business Associations | F156: 81 | G156: 44537 | H156: 2021 | I156: 4 | J156: 1–5 years | K156: 0 | L156: 425 15TH AVE E | M156: SEATTLE | N156: WA | O156: 98112 | P156: 1 | Q156: 8662020782342 | R156: 6.0331797e+15
A157: 15TH STREET VINTAGE | B157: 15TH STREET VINTAGE | C157: Corporation | D157: 459510 | E157: Used Merchandise Retailers | F157: 45 | G157: 45383 | H157: 2024 | I157: 2 | J157: 1–5 years | K157: 0 | L157: 7346 15TH AVE NW | M157: SEATTLE | N157: WA | O157: 98117 | P157: 1 | Q157: 8750440791708 | R157: 6.0538627e+15
A158: 16 RAVENNA LLC | B158: 16 RAVENNA LLC | C158: LLC - Single Member | D158: 721191 | E158: Bed-and-Breakfast Inns | F158: 72 | G158: 45870 | H158: 2025 | I158: 1 | J158: 1–5 years | K158: 0 | L158: 522 W RIVERSIDE AVE | M158: SPOKANE | N158: WA | O158: 99201 | P158: 0 | Q158: 8877430805096 | R158: 6.0594872e+15
A159: 16 VISIONS LLC | B159: 16 VISIONS LLC | C159: LLC - Multi Member | D159: 513199 | E159: All Other Publishers | F159: 51 | G159: 37257 | H159: 2002 | I159: 24 | J159: More than 20 years | K159: 0 | L159: 1106 18TH AVE | M159: SEATTLE | N159: WA | O159: 98122 | P159: 1 | Q159: 5526650557086 | R159: 6.0216465e+15
A160: 1601 DEXTER AVE N SEA LLC | B160: LAKE UNION EATS | C160: LLC - Single Member | D160: 531190 | E160: Lessors of Other Real Estate Property | F160: 53 | G160: 44838 | H160: 2022 | I160: 3 | J160: 1–5 years | K160: 0 | L160: 1601 DEXTER AVE N | M160: SEATTLE | N160: WA | O160: 98109 | P160: 1 | Q160: 8758370792535 | R160: 6.0471768e+15
A161: 1608 LLC | B161: THE ATTIC | C161: LLC - Multi Member | D161: 722511 | E161: Full-Service Restaurants | F161: 72 | G161: 45019 | H161: 2023 | I161: 3 | J161: 1–5 years | K161: 0 | L161: 4226 E MADISON ST | M161: SEATTLE | N161: WA | O161: 98112 | P161: 1 | Q161: 8670220783183 | R161: 6.049858e+15
A162: 1611 HOLDINGS GROUP LLC | B162: 1611 HOLDINGS GROUP | C162: LLC - Multi Member | D162: 541611 | E162: Administrative Management and General Management Consulting Services | F162: 54 | G162: 42552 | H162: 2016 | I162: 10 | J162: 6–10 years | K162: 0 | L162: 1611 10TH AVE W | M162: SEATTLE | N162: WA | O162: 98119 | P162: 1 | Q162: 7987870711674 | R162: 6.0400235e+15
A163: 1613 5TH AVE W STR | B163: 1613 5TH AVE W STR | C163: Sole proprietorship | D163: 721191 | E163: Bed-and-Breakfast Inns | F163: 72 | G163: 46148 | H163: 2026 | I163: 0 | J163: Less than 1 year | K163: 0 | L163: 1613 5TH AVE W | M163: SEATTLE | N163: WA | O163: 98119 | P163: 1 | Q163: 8921040809794
...

Sheet Ownership by Age
A3: License Count | B3: Business Age Group
A4: Ownership Type | B4: Less than 1 year | C4: 1–5 years | D4: 6–10 years | E4: 11–20 years | F4: More than 20 years | G4: Future start date | H4: Grand Total
A5: Association | B5: 1 | C5: 9 | D5: 17 | E5: 61 | F5: 21 | H5: 109
A6: Corporation | B6: 104 | C6: 478 | D6: 515 | E6: 831 | F6: 1168 | G6: 3 | H6: 3099
A7: General Partnership | B7: 3 | C7: 15 | D7: 9 | E7: 22 | F7: 38 | H7: 87
A8: Limited Liability Limited Ptrs | B8: 2 | C8: 45 | D8: 58 | E8: 3 | H8: 108
A9: Limited Liability Ptrs LLP | B9: 13 | C9: 37 | D9: 13 | E9: 11 | F9: 14 | H9: 88
A10: Limited Partnership | B10: 2 | C10: 7 | D10: 9 | E10: 2 | H10: 20
A11: LLC - Multi Member | B11: 147 | C11: 628 | D11: 526 | E11: 1070 | F11: 247 | G11: 4 | H11: 2622
A12: LLC - Single Member | B12: 545 | C12: 1839 | D12: 379 | E12: 21 | F12: 4 | G12: 9 | H12: 2797
A13: Municipality | B13: 1 | D13: 2 | E13: 1 | H13: 4
A14: Non Profit Corporation | B14: 14 | C14: 80 | D14: 30 | E14: 4 | F14: 8 | G14: 1 | H14: 137
A15: Other | B15: 1 | C15: 7 | D15: 380 | E15: 13 | F15: 34 | H15: 435
A16: Professional Association | B16: 1 | C16: 3 | D16: 22 | E16: 59 | F16: 13 | H16: 98
A17: Sole proprietorship | B17: 220 | C17: 807 | D17: 714 | E17: 803 | F17: 735 | G17: 4 | H17: 3283
A18: Trust | C18: 2 | H18: 2
A19: Joint Venture | C19: 3 | D19: 2 | H19: 5
A20: Tribal Government | C20: 1 | H20: 1
A21: LLC Limited Liability Co | D21: 2 | H21: 2
A22: Grand Total | B22: 1054 | C22: 3961 | D22: 2678 | E22: 2901 | F22: 2282 | G22: 21 | H22: 12897
